Workbook

Sheet Row Data
A1: Sector | B1: Year | C1: Month | D1: Cereals and products | E1: Meat and fish | F1: Egg | G1: Milk and products | H1: Oils and fats | I1: Fruits | J1: Vegetables | K1: Pulses and products | L1: Sugar and Confectionery | M1: Spices | N1: Non-alcoholic beverages | O1: Prepared meals, snacks, sweets etc. | P1: Food and beverages | Q1: Pan, tobacco and intoxicants | R1: Clothing | S1: Footwear | T1: Clothing and footwear | U1: Housing | V1: Fuel and light | W1: Household goods and services | X1: Health | Y1: Transport and communication | Z1: Recreation and amusement | AA1: Education | AB1: Personal care and effects | AC1: Miscellaneous | AD1: General index
A2: Rural | B2: 2013 | C2: January | D2: 107.5 | E2: 106.3 | F2: 108.1 | G2: 104.9 | H2: 106.1 | I2: 103.9 | J2: 101.9 | K2: 106.1 | L2: 106.8 | M2: 103.1 | N2: 104.8 | O2: 106.7 | P2: 105.5 | Q2: 105.1 | R2: 106.5 | S2: 105.8 | T2: 106.4 | V2: 105.5 | W2: 104.8 | X2: 104 | Y2: 103.3 | Z2: 103.4 | AA2: 103.8 | AB2: 104.7 | AC2: 104 | AD2: 105.1
A3: Urban | B3: 2013 | C3: January | D3: 110.5 | E3: 109.1 | F3: 113 | G3: 103.6 | H3: 103.4 | I3: 102.3 | J3: 102.9 | K3: 105.8 | L3: 105.1 | M3: 101.8 | N3: 105.1 | O3: 107.9 | P3: 105.9 | Q3: 105.2 | R3: 105.9 | S3: 105 | T3: 105.8 | U3: 100.3 | V3: 105.4 | W3: 104.8 | X3: 104.1 | Y3: 103.2 | Z3: 102.9 | AA3: 103.5 | AB3: 104.3 | AC3: 103.7 | AD3: 104
A4: Rural+Urban | B4: 2013 | C4: January | D4: 108.4 | E4: 107.3 | F4: 110 | G4: 104.4 | H4: 105.1 | I4: 103.2 | J4: 102.2 | K4: 106 | L4: 106.2 | M4: 102.7 | N4: 104.9 | O4: 107.3 | P4: 105.6 | Q4: 105.1 | R4: 106.3 | S4: 105.5 | T4: 106.2 | U4: 100.3 | V4: 105.5 | W4: 104.8 | X4: 104 | Y4: 103.2 | Z4: 103.1 | AA4: 103.6 | AB4: 104.5 | AC4: 103.9 | AD4: 104.6
A5: Rural | B5: 2013 | C5: February | D5: 109.2 | E5: 108.7 | F5: 110.2 | G5: 105.4 | H5: 106.7 | I5: 104 | J5: 102.4 | K5: 105.9 | L5: 105.7 | M5: 103.1 | N5: 105.1 | O5: 107.7 | P5: 106.3 | Q5: 105.6 | R5: 107.1 | S5: 106.3 | T5: 107 | V5: 106.2 | W5: 105.2 | X5: 104.4 | Y5: 103.9 | Z5: 104 | AA5: 104.1 | AB5: 104.6 | AC5: 104.4 | AD5: 105.8
A6: Urban | B6: 2013 | C6: February | D6: 112.9 | E6: 112.9 | F6: 116.9 | G6: 104 | H6: 103.5 | I6: 103.1 | J6: 104.9 | K6: 104.1 | L6: 103.8 | M6: 102.3 | N6: 106 | O6: 109 | P6: 107.2 | Q6: 106 | R6: 106.6 | S6: 105.5 | T6: 106.4 | U6: 100.4 | V6: 105.7 | W6: 105.2 | X6: 104.7 | Y6: 104.4 | Z6: 103.3 | AA6: 103.7 | AB6: 104.3 | AC6: 104.3 | AD6: 104.7
A7: Rural+Urban | B7: 2013 | C7: February | D7: 110.4 | E7: 110.2 | F7: 112.8 | G7: 104.9 | H7: 105.5 | I7: 103.6 | J7: 103.2 | K7: 105.3 | L7: 105.1 | M7: 102.8 | N7: 105.5 | O7: 108.3 | P7: 106.6 | Q7: 105.7 | R7: 106.9 | S7: 106 | T7: 106.8 | U7: 100.4 | V7: 106 | W7: 105.2 | X7: 104.5 | Y7: 104.2 | Z7: 103.6 | AA7: 103.9 | AB7: 104.5 | AC7: 104.4 | AD7: 105.3
A8: Rural | B8: 2013 | C8: March | D8: 110.2 | E8: 108.8 | F8: 109.9 | G8: 105.6 | H8: 106.2 | I8: 105.7 | J8: 101.4 | K8: 105.7 | L8: 105 | M8: 103.3 | N8: 105.6 | O8: 108.2 | P8: 106.6 | Q8: 106.5 | R8: 107.6 | S8: 106.8 | T8: 107.5 | V8: 106.1 | W8: 105.6 | X8: 104.7 | Y8: 104.6 | Z8: 104 | AA8: 104.3 | AB8: 104.3 | AC8: 104.6 | AD8: 106
A9: Urban | B9: 2013 | C9: March | D9: 113.9 | E9: 111.4 | F9: 113.2 | G9: 104.3 | H9: 102.7 | I9: 104.9 | J9: 103.8 | K9: 103.5 | L9: 102.6 | M9: 102.4 | N9: 107 | O9: 109.8 | P9: 107.3 | Q9: 106.8 | R9: 107.2 | S9: 106 | T9: 107 | U9: 100.4 | V9: 106 | W9: 105.7 | X9: 105.2 | Y9: 105.5 | Z9: 103.5 | AA9: 103.8 | AB9: 104.2 | AC9: 104.9 | AD9: 105
A10: Rural+Urban | B10: 2013 | C10: March | D10: 111.4 | E10: 109.7 | F10: 111.2 | G10: 105.1 | H10: 104.9 | I10: 105.3 | J10: 102.2 | K10: 105 | L10: 104.2 | M10: 103 | N10: 106.2 | O10: 108.9 | P10: 106.9 | Q10: 106.6 | R10: 107.4 | S10: 106.5 | T10: 107.3 | U10: 100.4 | V10: 106.1 | W10: 105.6 | X10: 104.9 | Y10: 105.1 | Z10: 103.7 | AA10: 104 | AB10: 104.3 | AC10: 104.7 | AD10: 105.5
A11: Rural | B11: 2013 | C11: April | D11: 110.2 | E11: 109.5 | F11: 106.9 | G11: 106.3 | H11: 105.7 | I11: 108.3 | J11: 103.4 | K11: 105.7 | L11: 104.2 | M11: 103.2 | N11: 106.5 | O11: 108.8 | P11: 107.1 | Q11: 107.1 | R11: 108.1 | S11: 107.4 | T11: 108 | V11: 106.5 | W11: 106.1 | X11: 105.1 | Y11: 104.4 | Z11: 104.5 | AA11: 104.8 | AB11: 102.7 | AC11: 104.6 | AD11: 106.4
A12: Urban | B12: 2013 | C12: April | D12: 114.6 | E12: 113.4 | F12: 106 | G12: 104.7 | H12: 102.1 | I12: 109.5 | J12: 109.7 | K12: 104.6 | L12: 102 | M12: 103.5 | N12: 108.2 | O12: 110.6 | P12: 108.8 | Q12: 108.5 | R12: 107.9 | S12: 106.4 | T12: 107.7 | U12: 100.5 | V12: 106.4 | W12: 106.5 | X12: 105.7 | Y12: 105 | Z12: 104 | AA12: 105.2 | AB12: 103.2 | AC12: 105.1 | AD12: 105.7
A13: Rural+Urban | B13: 2013 | C13: April | D13: 111.6 | E13: 110.9 | F13: 106.6 | G13: 105.7 | H13: 104.4 | I13: 108.9 | J13: 105.5 | K13: 105.3 | L13: 103.5 | M13: 103.3 | N13: 107.2 | O13: 109.6 | P13: 107.7 | Q13: 107.5 | R13: 108 | S13: 107 | T13: 107.9 | U13: 100.5 | V13: 106.5 | W13: 106.3 | X13: 105.3 | Y13: 104.7 | Z13: 104.2 | AA13: 105 | AB13: 102.9 | AC13: 104.8 | AD13: 106.1
A14: Rural | B14: 2013 | C14: May | D14: 110.9 | E14: 109.8 | F14: 105.9 | G14: 107.5 | H14: 105.3 | I14: 108.1 | J14: 107.3 | K14: 106.1 | L14: 103.7 | M14: 104 | N14: 107.4 | O14: 109.9 | P14: 108.1 | Q14: 108.1 | R14: 108.8 | S14: 107.9 | T14: 108.6 | V14: 107.5 | W14: 106.8 | X14: 105.7 | Y14: 104.1 | Z14: 105 | AA14: 105.5 | AB14: 102.1 | AC14: 104.8 | AD14: 107.2
A15: Urban | B15: 2013 | C15: May | D15: 115.4 | E15: 114.2 | F15: 102.7 | G15: 105.5 | H15: 101.5 | I15: 110.6 | J15: 123.7 | K15: 105.2 | L15: 101.9 | M15: 105 | N15: 109.1 | O15: 111.3 | P15: 111.1 | Q15: 109.8 | R15: 108.5 | S15: 106.7 | T15: 108.3 | U15: 100.5 | V15: 107.2 | W15: 107.1 | X15: 106.2 | Y15: 103.9 | Z15: 104.6 | AA15: 105.7 | AB15: 102.6 | AC15: 104.9 | AD15: 106.6
A16: Rural+Urban | B16: 2013 | C16: May | D16: 112.3 | E16: 111.3 | F16: 104.7 | G16: 106.8 | H16: 103.9 | I16: 109.3 | J16: 112.9 | K16: 105.8 | L16: 103.1 | M16: 104.3 | N16: 108.1 | O16: 110.5 | P16: 109.2 | Q16: 108.6 | R16: 108.7 | S16: 107.4 | T16: 108.5 | U16: 100.5 | V16: 107.4 | W16: 106.9 | X16: 105.9 | Y16: 104 | Z16: 104.8 | AA16: 105.6 | AB16: 102.3 | AC16: 104.8 | AD16: 106.9
A17: Rural | B17: 2013 | C17: June | D17: 112.3 | E17: 112.1 | F17: 108.1 | G17: 108.3 | H17: 105.9 | I17: 109.2 | J17: 118 | K17: 106.8 | L17: 104.1 | M17: 105.4 | N17: 108.2 | O17: 111 | P17: 110.6 | Q17: 109 | R17: 109.7 | S17: 108.8 | T17: 109.5 | V17: 108.5 | W17: 107.5 | X17: 106.3 | Y17: 105 | Z17: 105.6 | AA17: 106.5 | AB17: 102.5 | AC17: 105.5 | AD17: 108.9
A18: Urban | B18: 2013 | C18: June | D18: 117 | E18: 120.1 | F18: 112.5 | G18: 107.3 | H18: 101.3 | I18: 112.4 | J18: 143.6 | K18: 105.4 | L18: 101.4 | M18: 106.4 | N18: 110 | O18: 112.2 | P18: 115 | Q18: 110.9 | R18: 109.2 | S18: 107.2 | T18: 108.9 | U18: 106.6 | V18: 108 | W18: 107.7 | X18: 106.5 | Y18: 105.2 | Z18: 105.2 | AA18: 108.1 | AB18: 103.3 | AC18: 106.1 | AD18: 109.7
A19: Rural+Urban | B19: 2013 | C19: June | D19: 113.8 | E19: 114.9 | F19: 109.8 | G19: 107.9 | H19: 104.2 | I19: 110.7 | J19: 126.7 | K19: 106.3 | L19: 103.2 | M19: 105.7 | N19: 109 | O19: 111.6 | P19: 112.2 | Q19: 109.5 | R19: 109.5 | S19: 108.1 | T19: 109.3 | U19: 106.6 | V19: 108.3 | W19: 107.6 | X19: 106.4 | Y19: 105.1 | Z19: 105.4 | AA19: 107.4 | AB19: 102.8 | AC19: 105.8 | AD19: 109.3
A20: Rural | B20: 2013 | C20: July | D20: 113.4 | E20: 114.9 | F20: 110.5 | G20: 109.3 | H20: 106.2 | I20: 110.3 | J20: 129.2 | K20: 107.1 | L20: 104.3 | M20: 106.4 | N20: 109.1 | O20: 112.1 | P20: 113.1 | Q20: 109.8 | R20: 110.5 | S20: 109.5 | T20: 110.3 | V20: 109.5 | W20: 108.3 | X20: 106.9 | Y20: 106.8 | Z20: 106.4 | AA20: 107.8 | AB20: 102.5 | AC20: 106.5 | AD20: 110.7
A21: Urban | B21: 2013 | C21: July | D21: 117.8 | E21: 119.2 | F21: 114 | G21: 108.3 | H21: 101.1 | I21: 113.2 | J21: 160.9 | K21: 105.1 | L21: 101.3 | M21: 107.5 | N21: 110.4 | O21: 113.1 | P21: 117.5 | Q21: 111.7 | R21: 109.8 | S21: 107.8 | T21: 109.5 | U21: 107.7 | V21: 108.6 | W21: 108.1 | X21: 107.1 | Y21: 107.3 | Z21: 105.9 | AA21: 110.1 | AB21: 103.2 | AC21: 107.3 | AD21: 111.4
A22: Rural+Urban | B22: 2013 | C22: July | D22: 114.8 | E22: 116.4 | F22: 111.9 | G22: 108.9 | H22: 104.3 | I22: 111.7 | J22: 140 | K22: 106.4 | L22: 103.3 | M22: 106.8 | N22: 109.6 | O22: 112.6 | P22: 114.7 | Q22: 110.3 | R22: 110.2 | S22: 108.8 | T22: 110 | U22: 107.7 | V22: 109.2 | W22: 108.2 | X22: 107 | Y22: 107.1 | Z22: 106.1 | AA22: 109.1 | AB22: 102.8 | AC22: 106.9 | AD22: 111
A23: Rural | B23: 2013 | C23: August | D23: 114.3 | E23: 115.4 | F23: 111.1 | G23: 110 | H23: 106.4 | I23: 110.8 | J23: 138.9 | K23: 107.4 | L23: 104.1 | M23: 106.9 | N23: 109.7 | O23: 112.6 | P23: 114.9 | Q23: 110.7 | R23: 111.3 | S23: 110.2 | T23: 111.1 | V23: 109.9 | W23: 108.7 | X23: 107.5 | Y23: 107.8 | Z23: 106.8 | AA23: 108.7 | AB23: 105 | AC23: 107.5 | AD23: 112.1
A24: Urban | B24: 2013 | C24: August | D24: 118.3 | E24: 120.4 | F24: 112.7 | G24: 108.9 | H24: 101.1 | I24: 108.7 | J24: 177 | K24: 104.7 | L24: 101 | M24: 108.5 | N24: 110.9 | O24: 114.3 | P24: 119.6 | Q24: 112.4 | R24: 110.6 | S24: 108.3 | T24: 110.2 | U24: 108.9 | V24: 109.3 | W24: 108.7 | X24: 107.6 | Y24: 108.1 | Z24: 106.5 | AA24: 110.8 | AB24: 106 | AC24: 108.3 | AD24: 112.7
A25: Rural+Urban | B25: 2013 | C25: August | D25: 115.6 | E25: 117.2 | F25: 111.7 | G25: 109.6 | H25: 104.5 | I25: 109.8 | J25: 151.8 | K25: 106.5 | L25: 103.1 | M25: 107.4 | N25: 110.2 | O25: 113.4 | P25: 116.6 | Q25: 111.2 | R25: 111 | S25: 109.4 | T25: 110.7 | U25: 108.9 | V25: 109.7 | W25: 108.7 | X25: 107.5 | Y25: 108 | Z25: 106.6 | AA25: 109.9 | AB25: 105.4 | AC25: 107.9 | AD25: 112.4
A26: Rural | B26: 2013 | C26: September | D26: 115.4 | E26: 115.7 | F26: 111.7 | G26: 111 | H26: 107.4 | I26: 110.9 | J26: 154 | K26: 108.1 | L26: 104.2 | M26: 107.9 | N26: 110.4 | O26: 114 | P26: 117.8 | Q26: 111.7 | R26: 112.7 | S26: 111.4 | T26: 112.5 | V26: 111.1 | W26: 109.6 | X26: 108.3 | Y26: 109.3 | Z26: 107.7 | AA26: 109.8 | AB26: 106.7 | AC26: 108.7 | AD26: 114.2
A27: Urban | B27: 2013 | C27: September | D27: 118.6 | E27: 119.1 | F27: 113.2 | G27: 109.6 | H27: 101.7 | I27: 103.2 | J27: 174.3 | K27: 105.1 | L27: 100.8 | M27: 109.1 | N27: 111.1 | O27: 115.4 | P27: 119.2 | Q27: 112.9 | R27: 111.4 | S27: 109 | T27: 111.1 | U27: 109.7 | V27: 109.5 | W27: 109.6 | X27: 107.9 | Y27: 110.4 | Z27: 107.4 | AA27: 111.2 | AB27: 106.9 | AC27: 109.4 | AD27: 113.2
A28: Rural+Urban | B28: 2013 | C28: September | D28: 116.4 | E28: 116.9 | F28: 112.3 | G28: 110.5 | H28: 105.3 | I28: 107.3 | J28: 160.9 | K28: 107.1 | L28: 103.1 | M28: 108.3 | N28: 110.7 | O28: 114.6 | P28: 118.3 | Q28: 112 | R28: 112.2 | S28: 110.4 | T28: 111.9 | U28: 109.7 | V28: 110.5 | W28: 109.6 | X28: 108.1 | Y28: 109.9 | Z28: 107.5 | AA28: 110.6 | AB28: 106.8 | AC28: 109 | AD28: 113.7
A29: Rural | B29: 2013 | C29: October | D29: 116.3 | E29: 115.4 | F29: 112.6 | G29: 111.7 | H29: 107.7 | I29: 113.2 | J29: 164.9 | K29: 108.3 | L29: 103.9 | M29: 108.2 | N29: 111.1 | O29: 114.9 | P29: 119.8 | Q29: 112.2 | R29: 113.6 | S29: 112.3 | T29: 113.4 | V29: 111.6 | W29: 110.4 | X29: 108.9 | Y29: 109.3 | Z29: 108.3 | AA29: 110.2 | AB29: 107.5 | AC29: 109.1 | AD29: 115.5
A30: Urban | B30: 2013 | C30: October | D30: 118.9 | E30: 118.1 | F30: 114.5 | G30: 110.4 | H30: 102.3 | I30: 106.2 | J30: 183.5 | K30: 105.3 | L30: 100.2 | M30: 109.6 | N30: 111.4 | O30: 116 | P30: 120.8 | Q30: 113.5 | R30: 112.5 | S30: 109.7 | T30: 112 | U30: 110.5 | V30: 109.7 | W30: 110.2 | X30: 108.2 | Y30: 109.7 | Z30: 108 | AA30: 111.3 | AB30: 107.3 | AC30: 109.4 | AD30: 114
A31: Rural+Urban | B31: 2013 | C31: October | D31: 117.1 | E31: 116.3 | F31: 113.3 | G31: 111.2 | H31: 105.7 | I31: 109.9 | J31: 171.2 | K31: 107.3 | L31: 102.7 | M31: 108.7 | N31: 111.2 | O31: 115.4 | P31: 120.2 | Q31: 112.5 | R31: 113.2 | S31: 111.2 | T31: 112.8 | U31: 110.5 | V31: 110.9 | W31: 110.3 | X31: 108.6 | Y31: 109.5 | Z31: 108.1 | AA31: 110.8 | AB31: 107.4 | AC31: 109.2 | AD31: 114.8
A32: Rural | B32: 2013 | C32: November | D32: 117.3 | E32: 114.9 | F32: 116.2 | G32: 112.8 | H32: 108.9 | I32: 116.6 | J32: 178.1 | K32: 109.1 | L32: 103.6 | M32: 109 | N32: 111.8 | O32: 116 | P32: 122.5 | Q32: 112.8 | R32: 114.6 | S32: 113.1 | T32: 114.4 | V32: 112.6 | W32: 111.3 | X32: 109.7 | Y32: 109.6 | Z32: 108.7 | AA32: 111 | AB32: 108.2 | AC32: 109.8 | AD32: 117.4
A33: Urban | B33: 2013 | C33: November | D33: 119.8 | E33: 116.3 | F33: 122.6 | G33: 112 | H33: 103.2 | I33: 110 | J33: 192.8 | K33: 106.3 | L33: 99.5 | M33: 110.3 | N33: 111.8 | O33: 117.1 | P33: 122.9 | Q33: 114.1 | R33: 113.5 | S33: 110.3 | T33: 113 | U33: 111.1 | V33: 110 | W33: 110.9 | X33: 108.6 | Y33: 109.5 | Z33: 108.5 | AA33: 111.3 | AB33: 107.9 | AC33: 109.6 | AD33: 115
A34: Rural+Urban | B34: 2013 | C34: November | D34: 118.1 | E34: 115.4 | F34: 118.7 | G34: 112.5 | H34: 106.8 | I34: 113.5 | J34: 183.1 | K34: 108.2 | L34: 102.2 | M34: 109.4 | N34: 111.8 | O34: 116.5 | P34: 122.6 | Q34: 113.1 | R34: 114.2 | S34: 111.9 | T34: 113.8 | U34: 111.1 | V34: 111.6 | W34: 111.1 | X34: 109.3 | Y34: 109.5 | Z34: 108.6 | AA34: 111.2 | AB34: 108.1 | AC34: 109.7 | AD34: 116.3
A35: Rural | B35: 2013 | C35: December | D35: 118.4 | E35: 115.9 | F35: 120.4 | G35: 113.8 | H35: 109.5 | I35: 115.5 | J35: 145.7 | K35: 109.5 | L35: 102.9 | M35: 109.8 | N35: 112.1 | O35: 116.8 | P35: 118.7 | Q35: 113.6 | R35: 115.8 | S35: 114 | T35: 115.5 | V35: 112.8 | W35: 112.1 | X35: 110.1 | Y35: 109.9 | Z35: 109.2 | AA35: 111.6 | AB35: 108.1 | AC35: 110.1 | AD35: 115.5
A36: Urban | B36: 2013 | C36: December | D36: 120.5 | E36: 118.1 | F36: 128.5 | G36: 112.8 | H36: 103.4 | I36: 110.7 | J36: 144.8 | K36: 107.1 | L36: 98.6 | M36: 111.9 | N36: 112.1 | O36: 118.1 | P36: 117.8 | Q36: 115 | R36: 114.2 | S36: 110.9 | T36: 113.7 | U36: 110.7 | V36: 110.4 | W36: 111.3 | X36: 109 | Y36: 109.7 | Z36: 108.9 | AA36: 111.4 | AB36: 107.7 | AC36: 109.8 | AD36: 113.3
A37: Rural+Urban | B37: 2013 | C37: December | D37: 119.1 | E37: 116.7 | F37: 123.5 | G37: 113.4 | H37: 107.3 | I37: 113.3 | J37: 145.4 | K37: 108.7 | L37: 101.5 | M37: 110.5 | N37: 112.1 | O37: 117.4 | P37: 118.4 | Q37: 114 | R37: 115.2 | S37: 112.7 | T37: 114.8 | U37: 110.7 | V37: 111.9 | W37: 111.7 | X37: 109.7 | Y37: 109.8 | Z37: 109 | AA37: 111.5 | AB37: 107.9 | AC37: 110 | AD37: 114.5
A38: Rural | B38: 2014 | C38: January | D38: 118.9 | E38: 117.1 | F38: 120.5 | G38: 114.4 | H38: 109 | I38: 115.5 | J38: 123.9 | K38: 109.6 | L38: 101.8 | M38: 110.2 | N38: 112.4 | O38: 117.3 | P38: 116 | Q38: 114 | R38: 116.5 | S38: 114.5 | T38: 116.2 | V38: 113 | W38: 112.6 | X38: 110.6 | Y38: 110.5 | Z38: 109.6 | AA38: 111.8 | AB38: 108.3 | AC38: 110.6 | AD38: 114.2
A39: Urban | B39: 2014 | C39: January | D39: 121.2 | E39: 122 | F39: 129.9 | G39: 113.6 | H39: 102.9 | I39: 112.1 | J39: 118.9 | K39: 107.5 | L39: 96.9 | M39: 112.7 | N39: 112.1 | O39: 119 | P39: 115.5 | Q39: 115.7 | R39: 114.8 | S39: 111.3 | T39: 114.3 | U39: 111.6 | V39: 111 | W39: 111.9 | X39: 109.7 | Y39: 110.8 | Z39: 109.8 | AA39: 111.5 | AB39: 108 | AC39: 110.5 | AD39: 112.9
A40: Rural+Urban | B40: 2014 | C40: January | D40: 119.6 | E40: 118.8 | F40: 124.1 | G40: 114.1 | H40: 106.8 | I40: 113.9 | J40: 122.2 | K40: 108.9 | L40: 100.2 | M40: 111 | N40: 112.3 | O40: 118.1 | P40: 115.8 | Q40: 114.5 | R40: 115.8 | S40: 113.2 | T40: 115.4 | U40: 111.6 | V40: 112.2 | W40: 112.3 | X40: 110.3 | Y40: 110.7 | Z40: 109.7 | AA40: 111.6 | AB40: 108.2 | AC40: 110.6 | AD40: 113.6
...

Sheet Problem Statement
A1: 1. Based on the latest month's data, identify the contribution of different broader categories (food, energy, transportation, education, etc.) towards the CPI basket. | B1: Broader categories (buckets) can be created by combining similar categories into one bucket. | C1: Example: Meals, Beverages, Cereals can be clubbed to create a "Food" category, etc. | D1: Which broader category has the highest contribution towards CPI calculation? | E1: Contribution is calculated by evaluating the underlying index values for the broader category and should add to 100% when contribution from different broader categories are added.
A2: 2. A trend of Y-o-Y increase in CPI (rural + urban) inflation starting 2017 for the entire basket of products combined. | B2: Create a graph depicting the growth rate Y-o-Y and identify the year with highest inflation rate. | C2: Highlight the reason why the year has the highest inflation (based on research).
A3: 3. With India's retail inflation reaching a 3-month high of 5.55% in November 2023, largely due to a sharp rise in food prices. Analyze the following for 12 months ending May'23. | B3: Investigate trends in the prices of broader food bucket category and evaluate month-on-month changes. Highlight month with highest and lowest food inflation. | C3: Identify the absolute changes in inflation over the same 12 months period and identify the biggest individual category contributor (only within broader food category) towards inflation.
A4: 4. Investigate how the onset and progression of the COVID-19 pandemic affected inflation rates in India. Analyze the impact of key pandemic milestone (first lockdown) on the CPI inflation %, especially focus on categories like healthcare, food, and essential services. | B4: Hint: You can consider Mar'20 as the onset of covid, and can compare the inflation trend before and after Mar'20 to see if there is a change in inflation % before and after.
A5: 5. Investigate how major global economic events (like imported crude oil price fluctuations) have influence India's inflation. This can include an analysis of imported goods and their price trends. | B5: For the purpose of this analysis, focus only on the imported oil price fluctuations for years 2021 to 2023 (Month-on-month). | C5: Identify trends in oil price change with change in inflation prices of all the categories and identify category whose inflation prices strongly changes with fluctuations in imported oil price (Hint: you can use =CORREL function).

Sheet Data Preparation
A1: Sector | B1: Year | C1: Month | D1: Date | E1: General Index | F1: YoY Inflation % | G1: MoM Inflation % | H1: Food Index | I1: Food MoM % | J1: COVID Period
A2: ='Row Data'!A2 -> Rural | B2: ='Row Data'!B2 -> 2013 | C2: ='Row Data'!C2 -> January | D2: =DATE(B2,MATCH(C2,{"January","February","March","April","May","June","July","August","September","October","November","December"},0),1) -> 41275 | E2: ='Row Data'!AD2 -> 105.1 | F2: =IFERROR(E2/SUMIFS($E:$E,$A:$A,A2,$B:$B,B2-1,$C:$C,C2)-1,"") | G2: =IFERROR(E2/SUMIFS($E:$E,$A:$A,A2,$D:$D,EDATE(D2,-1))-1,"") | H2: ='Row Data'!P2 -> 105.5 | I2: =IFERROR(H2/SUMIFS($H:$H,$A:$A,A2,$D:$D,EDATE(D2,-1))-1,"") | J2: =IF(D2<DATE(2020,3,1),"Pre-COVID",IF(D2=DATE(2020,3,1),"COVID Onset / Mar-20",IF(D2<=DATE(2021,12,31),"COVID Period","Post-COVID"))) -> Pre-COVID
A3: ='Row Data'!A3 -> Urban | B3: ='Row Data'!B3 -> 2013 | C3: ='Row Data'!C3 -> January | D3: =DATE(B3,MATCH(C3,{"January","February","March","April","May","June","July","August","September","October","November","December"},0),1) -> 41275 | E3: ='Row Data'!AD3 -> 104 | F3: =IFERROR(E3/SUMIFS($E:$E,$A:$A,A3,$B:$B,B3-1,$C:$C,C3)-1,"") | G3: =IFERROR(E3/SUMIFS($E:$E,$A:$A,A3,$D:$D,EDATE(D3,-1))-1,"") | H3: ='Row Data'!P3 -> 105.9 | I3: =IFERROR(H3/SUMIFS($H:$H,$A:$A,A3,$D:$D,EDATE(D3,-1))-1,"") | J3: =IF(D3<DATE(2020,3,1),"Pre-COVID",IF(D3=DATE(2020,3,1),"COVID Onset / Mar-20",IF(D3<=DATE(2021,12,31),"COVID Period","Post-COVID"))) -> Pre-COVID
A4: ='Row Data'!A4 -> Rural+Urban | B4: ='Row Data'!B4 -> 2013 | C4: ='Row Data'!C4 -> January | D4: =DATE(B4,MATCH(C4,{"January","February","March","April","May","June","July","August","September","October","November","December"},0),1) -> 41275 | E4: ='Row Data'!AD4 -> 104.6 | F4: =IFERROR(E4/SUMIFS($E:$E,$A:$A,A4,$B:$B,B4-1,$C:$C,C4)-1,"") | G4: =IFERROR(E4/SUMIFS($E:$E,$A:$A,A4,$D:$D,EDATE(D4,-1))-1,"") | H4: ='Row Data'!P4 -> 105.6 | I4: =IFERROR(H4/SUMIFS($H:$H,$A:$A,A4,$D:$D,EDATE(D4,-1))-1,"") | J4: =IF(D4<DATE(2020,3,1),"Pre-COVID",IF(D4=DATE(2020,3,1),"COVID Onset / Mar-20",IF(D4<=DATE(2021,12,31),"COVID Period","Post-COVID"))) -> Pre-COVID
A5: ='Row Data'!A5 -> Rural | B5: ='Row Data'!B5 -> 2013 | C5: ='Row Data'!C5 -> February | D5: =DATE(B5,MATCH(C5,{"January","February","March","April","May","June","July","August","September","October","November","December"},0),1) -> 41306 | E5: ='Row Data'!AD5 -> 105.8 | F5: =IFERROR(E5/SUMIFS($E:$E,$A:$A,A5,$B:$B,B5-1,$C:$C,C5)-1,"") | G5: =IFERROR(E5/SUMIFS($E:$E,$A:$A,A5,$D:$D,EDATE(D5,-1))-1,"") -> 0.0066603235 | H5: ='Row Data'!P5 -> 106.3 | I5: =IFERROR(H5/SUMIFS($H:$H,$A:$A,A5,$D:$D,EDATE(D5,-1))-1,"") -> 0.0075829384 | J5: =IF(D5<DATE(2020,3,1),"Pre-COVID",IF(D5=DATE(2020,3,1),"COVID Onset / Mar-20",IF(D5<=DATE(2021,12,31),"COVID Period","Post-COVID"))) -> Pre-COVID
A6: ='Row Data'!A6 -> Urban | B6: ='Row Data'!B6 -> 2013 | C6: ='Row Data'!C6 -> February | D6: =DATE(B6,MATCH(C6,{"January","February","March","April","May","June","July","August","September","October","November","December"},0),1) -> 41306 | E6: ='Row Data'!AD6 -> 104.7 | F6: =IFERROR(E6/SUMIFS($E:$E,$A:$A,A6,$B:$B,B6-1,$C:$C,C6)-1,"") | G6: =IFERROR(E6/SUMIFS($E:$E,$A:$A,A6,$D:$D,EDATE(D6,-1))-1,"") -> 0.0067307692 | H6: ='Row Data'!P6 -> 107.2 | I6: =IFERROR(H6/SUMIFS($H:$H,$A:$A,A6,$D:$D,EDATE(D6,-1))-1,"") -> 0.012275732 | J6: =IF(D6<DATE(2020,3,1),"Pre-COVID",IF(D6=DATE(2020,3,1),"COVID Onset / Mar-20",IF(D6<=DATE(2021,12,31),"COVID Period","Post-COVID"))) -> Pre-COVID
A7: ='Row Data'!A7 -> Rural+Urban | B7: ='Row Data'!B7 -> 2013 | C7: ='Row Data'!C7 -> February | D7: =DATE(B7,MATCH(C7,{"January","February","March","April","May","June","July","August","September","October","November","December"},0),1) -> 41306 | E7: ='Row Data'!AD7 -> 105.3 | F7: =IFERROR(E7/SUMIFS($E:$E,$A:$A,A7,$B:$B,B7-1,$C:$C,C7)-1,"") | G7: =IFERROR(E7/SUMIFS($E:$E,$A:$A,A7,$D:$D,EDATE(D7,-1))-1,"") -> 0.0066921606 | H7: ='Row Data'!P7 -> 106.6 | I7: =IFERROR(H7/SUMIFS($H:$H,$A:$A,A7,$D:$D,EDATE(D7,-1))-1,"") -> 0.009469697 | J7: =IF(D7<DATE(2020,3,1),"Pre-COVID",IF(D7=DATE(2020,3,1),"COVID Onset / Mar-20",IF(D7<=DATE(2021,12,31),"COVID Period","Post-COVID"))) -> Pre-COVID
A8: ='Row Data'!A8 -> Rural | B8: ='Row Data'!B8 -> 2013 | C8: ='Row Data'!C8 -> March | D8: =DATE(B8,MATCH(C8,{"January","February","March","April","May","June","July","August","September","October","November","December"},0),1) -> 41334 | E8: ='Row Data'!AD8 -> 106 | F8: =IFERROR(E8/SUMIFS($E:$E,$A:$A,A8,$B:$B,B8-1,$C:$C,C8)-1,"") | G8: =IFERROR(E8/SUMIFS($E:$E,$A:$A,A8,$D:$D,EDATE(D8,-1))-1,"") -> 0.0018903592 | H8: ='Row Data'!P8 -> 106.6 | I8: =IFERROR(H8/SUMIFS($H:$H,$A:$A,A8,$D:$D,EDATE(D8,-1))-1,"") -> 0.0028222013 | J8: =IF(D8<DATE(2020,3,1),"Pre-COVID",IF(D8=DATE(2020,3,1),"COVID Onset / Mar-20",IF(D8<=DATE(2021,12,31),"COVID Period","Post-COVID"))) -> Pre-COVID
A9: ='Row Data'!A9 -> Urban | B9: ='Row Data'!B9 -> 2013 | C9: ='Row Data'!C9 -> March | D9: =DATE(B9,MATCH(C9,{"January","February","March","April","May","June","July","August","September","October","November","December"},0),1) -> 41334 | E9: ='Row Data'!AD9 -> 105 | F9: =IFERROR(E9/SUMIFS($E:$E,$A:$A,A9,$B:$B,B9-1,$C:$C,C9)-1,"") | G9: =IFERROR(E9/SUMIFS($E:$E,$A:$A,A9,$D:$D,EDATE(D9,-1))-1,"") -> 0.0028653295 | H9: ='Row Data'!P9 -> 107.3 | I9: =IFERROR(H9/SUMIFS($H:$H,$A:$A,A9,$D:$D,EDATE(D9,-1))-1,"") -> 0.00093283582 | J9: =IF(D9<DATE(2020,3,1),"Pre-COVID",IF(D9=DATE(2020,3,1),"COVID Onset / Mar-20",IF(D9<=DATE(2021,12,31),"COVID Period","Post-COVID"))) -> Pre-COVID
A10: ='Row Data'!A10 -> Rural+Urban | B10: ='Row Data'!B10 -> 2013 | C10: ='Row Data'!C10 -> March | D10: =DATE(B10,MATCH(C10,{"January","February","March","April","May","June","July","August","September","October","November","December"},0),1) -> 41334 | E10: ='Row Data'!AD10 -> 105.5 | F10: =IFERROR(E10/SUMIFS($E:$E,$A:$A,A10,$B:$B,B10-1,$C:$C,C10)-1,"") | G10: =IFERROR(E10/SUMIFS($E:$E,$A:$A,A10,$D:$D,EDATE(D10,-1))-1,"") -> 0.0018993352 | H10: ='Row Data'!P10 -> 106.9 | I10: =IFERROR(H10/SUMIFS($H:$H,$A:$A,A10,$D:$D,EDATE(D10,-1))-1,"") -> 0.0028142589 | J10: =IF(D10<DATE(2020,3,1),"Pre-COVID",IF(D10=DATE(2020,3,1),"COVID Onset / Mar-20",IF(D10<=DATE(2021,12,31),"COVID Period","Post-COVID"))) -> Pre-COVID
A11: ='Row Data'!A11 -> Rural | B11: ='Row Data'!B11 -> 2013 | C11: ='Row Data'!C11 -> April | D11: =DATE(B11,MATCH(C11,{"January","February","March","April","May","June","July","August","September","October","November","December"},0),1) -> 41365 | E11: ='Row Data'!AD11 -> 106.4 | F11: =IFERROR(E11/SUMIFS($E:$E,$A:$A,A11,$B:$B,B11-1,$C:$C,C11)-1,"") | G11: =IFERROR(E11/SUMIFS($E:$E,$A:$A,A11,$D:$D,EDATE(D11,-1))-1,"") -> 0.0037735849 | H11: ='Row Data'!P11 -> 107.1 | I11: =IFERROR(H11/SUMIFS($H:$H,$A:$A,A11,$D:$D,EDATE(D11,-1))-1,"") -> 0.0046904315 | J11: =IF(D11<DATE(2020,3,1),"Pre-COVID",IF(D11=DATE(2020,3,1),"COVID Onset / Mar-20",IF(D11<=DATE(2021,12,31),"COVID Period","Post-COVID"))) -> Pre-COVID
A12: ='Row Data'!A12 -> Urban | B12: ='Row Data'!B12 -> 2013 | C12: ='Row Data'!C12 -> April | D12: =DATE(B12,MATCH(C12,{"January","February","March","April","May","June","July","August","September","October","November","December"},0),1) -> 41365 | E12: ='Row Data'!AD12 -> 105.7 | F12: =IFERROR(E12/SUMIFS($E:$E,$A:$A,A12,$B:$B,B12-1,$C:$C,C12)-1,"") | G12: =IFERROR(E12/SUMIFS($E:$E,$A:$A,A12,$D:$D,EDATE(D12,-1))-1,"") -> 0.0066666667 | H12: ='Row Data'!P12 -> 108.8 | I12: =IFERROR(H12/SUMIFS($H:$H,$A:$A,A12,$D:$D,EDATE(D12,-1))-1,"") -> 0.013979497 | J12: =IF(D12<DATE(2020,3,1),"Pre-COVID",IF(D12=DATE(2020,3,1),"COVID Onset / Mar-20",IF(D12<=DATE(2021,12,31),"COVID Period","Post-COVID"))) -> Pre-COVID
A13: ='Row Data'!A13 -> Rural+Urban | B13: ='Row Data'!B13 -> 2013 | C13: ='Row Data'!C13 -> April | D13: =DATE(B13,MATCH(C13,{"January","February","March","April","May","June","July","August","September","October","November","December"},0),1) -> 41365 | E13: ='Row Data'!AD13 -> 106.1 | F13: =IFERROR(E13/SUMIFS($E:$E,$A:$A,A13,$B:$B,B13-1,$C:$C,C13)-1,"") | G13: =IFERROR(E13/SUMIFS($E:$E,$A:$A,A13,$D:$D,EDATE(D13,-1))-1,"") -> 0.0056872038 | H13: ='Row Data'!P13 -> 107.7 | I13: =IFERROR(H13/SUMIFS($H:$H,$A:$A,A13,$D:$D,EDATE(D13,-1))-1,"") -> 0.0074836296 | J13: =IF(D13<DATE(2020,3,1),"Pre-COVID",IF(D13=DATE(2020,3,1),"COVID Onset / Mar-20",IF(D13<=DATE(2021,12,31),"COVID Period","Post-COVID"))) -> Pre-COVID
... A373: ='Row Data'!A373 -> Rural+Urban | B373: ='Row Data'!B373 -> 2023 | C373: ='Row Data'!C373 -> May | D373: =DATE(B373,MATCH(C373,{"January","February","March","April","May","June","July","August","September","October","November","December"},0),1) -> 45047 | E373: ='Row Data'!AD373 -> 179.1 | F373: =IFERROR(E373/SUMIFS($E:$E,$A:$A,A373,$B:$B,B373-1,$C:$C,C373)-1,"") -> 0.043098427 | G373: =IFERROR(E373/SUMIFS($E:$E,$A:$A,A373,$D:$D,EDATE(D373,-1))-1,"") -> 0.0056148231 | H373: ='Row Data'!P373 -> 179.1 | I373: =IFERROR(H373/SUMIFS($H:$H,$A:$A,A373,$D:$D,EDATE(D373,-1))-1,"") -> 0.0067453626 | J373: =IF(D373<DATE(2020,3,1),"Pre-COVID",IF(D373=DATE(2020,3,1),"COVID Onset / Mar-20",IF(D373<=DATE(2021,12,31),"COVID Period","Post-COVID"))) -> Post-COVID

Sheet Q1_CPI Contribution
A1: Broader Category | B1: Index Value | C1: Contribution % | D1: Raw Category
A2: Food | B2: =SUMIFS(INDEX('Row Data'!$A:$AD,0,MATCH(D2,'Row Data'!$1:$1,0)),'Row Data'!$A:$A,"Rural+Urban",'Row Data'!$B:$B,2023,'Row Data'!$C:$C,"April") -> 177.9 | C2: =IFERROR(B2/SUM($B$2:$B$12),0) -> 0.098772972 | D2: Food and beverages
A3: Pan, Tobacco & Intoxicants | B3: =SUMIFS(INDEX('Row Data'!$A:$AD,0,MATCH(D3,'Row Data'!$1:$1,0)),'Row Data'!$A:$A,"Rural+Urban",'Row Data'!$B:$B,2023,'Row Data'!$C:$C,"April") -> 200.6 | C3: =IFERROR(B3/SUM($B$2:$B$12),0) -> 0.11137638 | D3: Pan, tobacco and intoxicants
A4: Clothing & Footwear | B4: =SUMIFS(INDEX('Row Data'!$A:$AD,0,MATCH(D4,'Row Data'!$1:$1,0)),'Row Data'!$A:$A,"Rural+Urban",'Row Data'!$B:$B,2023,'Row Data'!$C:$C,"April") -> 185.7 | C4: =IFERROR(B4/SUM($B$2:$B$12),0) -> 0.10310366 | D4: Clothing and footwear
A5: Housing | B5: =SUMIFS(INDEX('Row Data'!$A:$AD,0,MATCH(D5,'Row Data'!$1:$1,0)),'Row Data'!$A:$A,"Rural+Urban",'Row Data'!$B:$B,2023,'Row Data'!$C:$C,"April") -> 0 | C5: =IFERROR(B5/SUM($B$2:$B$12),0) -> 0 | D5: Housing
A6: Fuel & Light | B6: =SUMIFS(INDEX('Row Data'!$A:$AD,0,MATCH(D6,'Row Data'!$1:$1,0)),'Row Data'!$A:$A,"Rural+Urban",'Row Data'!$B:$B,2023,'Row Data'!$C:$C,"April") -> 181.7 | C6: =IFERROR(B6/SUM($B$2:$B$12),0) -> 0.10088279 | D6: Fuel and light
A7: Household Goods & Services | B7: =SUMIFS(INDEX('Row Data'!$A:$AD,0,MATCH(D7,'Row Data'!$1:$1,0)),'Row Data'!$A:$A,"Rural+Urban",'Row Data'!$B:$B,2023,'Row Data'!$C:$C,"April") -> 174.6 | C7: =IFERROR(B7/SUM($B$2:$B$12),0) -> 0.096940758 | D7: Household goods and services
A8: Health | B8: =SUMIFS(INDEX('Row Data'!$A:$AD,0,MATCH(D8,'Row Data'!$1:$1,0)),'Row Data'!$A:$A,"Rural+Urban",'Row Data'!$B:$B,2023,'Row Data'!$C:$C,"April") -> 185 | C8: =IFERROR(B8/SUM($B$2:$B$12),0) -> 0.10271501 | D8: Health
A9: Transport & Communication | B9: =SUMIFS(INDEX('Row Data'!$A:$AD,0,MATCH(D9,'Row Data'!$1:$1,0)),'Row Data'!$A:$A,"Rural+Urban",'Row Data'!$B:$B,2023,'Row Data'!$C:$C,"April") -> 164.5 | C9: =IFERROR(B9/SUM($B$2:$B$12),0) -> 0.091333074 | D9: Transport and communication
A10: Recreation & Amusement | B10: =SUMIFS(INDEX('Row Data'!$A:$AD,0,MATCH(D10,'Row Data'!$1:$1,0)),'Row Data'!$A:$A,"Rural+Urban",'Row Data'!$B:$B,2023,'Row Data'!$C:$C,"April") -> 170.7 | C10: =IFERROR(B10/SUM($B$2:$B$12),0) -> 0.094775415 | D10: Recreation and amusement
A11: Education | B11: =SUMIFS(INDEX('Row Data'!$A:$AD,0,MATCH(D11,'Row Data'!$1:$1,0)),'Row Data'!$A:$A,"Rural+Urban",'Row Data'!$B:$B,2023,'Row Data'!$C:$C,"April") -> 176.4 | C11: =IFERROR(B11/SUM($B$2:$B$12),0) -> 0.097940148 | D11: Education
A12: Personal Care & Effects | B12: =SUMIFS(INDEX('Row Data'!$A:$AD,0,MATCH(D12,'Row Data'!$1:$1,0)),'Row Data'!$A:$A,"Rural+Urban",'Row Data'!$B:$B,2023,'Row Data'!$C:$C,"April") -> 184 | C12: =IFERROR(B12/SUM($B$2:$B$12),0) -> 0.10215979 | D12: Personal care and effects
A14: Total | C14: =SUM(C2:C12) -> 1
A15: Highest Contribution | B15: =INDEX(A2:A12,MATCH(MAX(C2:C12),C2:C12,0)) -> Pan, Tobacco & Intoxicants | C15: =MAX(C2:C12) -> 0.11137638

Sheet Q2_YoY Trend
A1: Year | B1: General Index | C1: YoY Inflation %
A2: 2017 | B2: =AVERAGEIFS('Data Preparation'!$E:$E,'Data Preparation'!$A:$A,"Rural+Urban",'Data Preparation'!$B:$B,A2) -> 133.5 | C2: =IFERROR(B2/AVERAGEIFS('Data Preparation'!$E:$E,'Data Preparation'!$A:$A,"Rural+Urban",'Data Preparation'!$B:$B,A2-1)-1,"") -> 0.033281734
A3: 2018 | B3: =AVERAGEIFS('Data Preparation'!$E:$E,'Data Preparation'!$A:$A,"Rural+Urban",'Data Preparation'!$B:$B,A3) -> 138.775 | C3: =IFERROR(B3/AVERAGEIFS('Data Preparation'!$E:$E,'Data Preparation'!$A:$A,"Rural+Urban",'Data Preparation'!$B:$B,A3-1)-1,"") -> 0.039513109
A4: 2019 | B4: =AVERAGEIFS('Data Preparation'!$E:$E,'Data Preparation'!$A:$A,"Rural+Urban",'Data Preparation'!$B:$B,A4) -> 144.18182 | C4: =IFERROR(B4/AVERAGEIFS('Data Preparation'!$E:$E,'Data Preparation'!$A:$A,"Rural+Urban",'Data Preparation'!$B:$B,A4-1)-1,"") -> 0.038961039
A5: 2020 | B5: =AVERAGEIFS('Data Preparation'!$E:$E,'Data Preparation'!$A:$A,"Rural+Urban",'Data Preparation'!$B:$B,A5) -> 127.81667 | C5: =IFERROR(B5/AVERAGEIFS('Data Preparation'!$E:$E,'Data Preparation'!$A:$A,"Rural+Urban",'Data Preparation'!$B:$B,A5-1)-1,"") -> -0.11350357
A6: 2021 | B6: =AVERAGEIFS('Data Preparation'!$E:$E,'Data Preparation'!$A:$A,"Rural+Urban",'Data Preparation'!$B:$B,A6) -> 161.45833 | C6: =IFERROR(B6/AVERAGEIFS('Data Preparation'!$E:$E,'Data Preparation'!$A:$A,"Rural+Urban",'Data Preparation'!$B:$B,A6-1)-1,"") -> 0.2632025
A7: 2022 | B7: =AVERAGEIFS('Data Preparation'!$E:$E,'Data Preparation'!$A:$A,"Rural+Urban",'Data Preparation'!$B:$B,A7) -> 172.15 | C7: =IFERROR(B7/AVERAGEIFS('Data Preparation'!$E:$E,'Data Preparation'!$A:$A,"Rural+Urban",'Data Preparation'!$B:$B,A7-1)-1,"") -> 0.066219355
A8: 2023 | B8: =AVERAGEIFS('Data Preparation'!$E:$E,'Data Preparation'!$A:$A,"Rural+Urban",'Data Preparation'!$B:$B,A8) -> 177.62 | C8: =IFERROR(B8/AVERAGEIFS('Data Preparation'!$E:$E,'Data Preparation'!$A:$A,"Rural+Urban",'Data Preparation'!$B:$B,A8-1)-1,"") -> 0.031774615
A10: Highest Inflation Year | B10: =INDEX(A2:A8,MATCH(MAX(C2:C8),C2:C8,0)) -> 2021 | C10: =MAX(C2:C8) -> 0.2632025
A11: Research Note | B11: Add researched explanation for the highest-inflation year here.

Sheet Q3_Food Inflation
A1: Month | B1: Food Index | C1: Food MoM % | D1: Absolute Change | F1: Highest Food Inflation | G1: Highest Month
A2: 44682 | B2: =AVERAGEIFS('Data Preparation'!$H:$H,'Data Preparation'!$A:$A,"Rural+Urban",'Data Preparation'!$D:$D,A2) -> 173.3 | C2: =IFERROR(B2/AVERAGEIFS('Data Preparation'!$H:$H,'Data Preparation'!$A:$A,"Rural+Urban",'Data Preparation'!$D:$D,EDATE(A2,-1))-1,"") -> 0.014637002 | D2: =B2-$B$2 -> 0 | F2: =MAX(C2:C13) -> 0.014637002 | G2: =INDEX(A2:A13,MATCH(MAX(C2:C13),C2:C13,0)) -> 44682
A3: 44713 | B3: =AVERAGEIFS('Data Preparation'!$H:$H,'Data Preparation'!$A:$A,"Rural+Urban",'Data Preparation'!$D:$D,A3) -> 174.9 | C3: =IFERROR(B3/AVERAGEIFS('Data Preparation'!$H:$H,'Data Preparation'!$A:$A,"Rural+Urban",'Data Preparation'!$D:$D,EDATE(A3,-1))-1,"") -> 0.0092325447 | D3: =B3-$B$2 -> 1.6
A4: 44743 | B4: =AVERAGEIFS('Data Preparation'!$H:$H,'Data Preparation'!$A:$A,"Rural+Urban",'Data Preparation'!$D:$D,A4) -> 175 | C4: =IFERROR(B4/AVERAGEIFS('Data Preparation'!$H:$H,'Data Preparation'!$A:$A,"Rural+Urban",'Data Preparation'!$D:$D,EDATE(A4,-1))-1,"") -> 0.00057175529 | D4: =B4-$B$2 -> 1.7 | F4: Lowest Food Inflation | G4: Lowest Month
A5: 44774 | B5: =AVERAGEIFS('Data Preparation'!$H:$H,'Data Preparation'!$A:$A,"Rural+Urban",'Data Preparation'!$D:$D,A5) -> 176.3 | C5: =IFERROR(B5/AVERAGEIFS('Data Preparation'!$H:$H,'Data Preparation'!$A:$A,"Rural+Urban",'Data Preparation'!$D:$D,EDATE(A5,-1))-1,"") -> 0.0074285714 | D5: =B5-$B$2 -> 3 | F5: =MIN(C2:C13) -> -0.01346046 | G5: =INDEX(A2:A13,MATCH(MIN(C2:C13),C2:C13,0)) -> 44896
A6: 44805 | B6: =AVERAGEIFS('Data Preparation'!$H:$H,'Data Preparation'!$A:$A,"Rural+Urban",'Data Preparation'!$D:$D,A6) -> 177.8 | C6: =IFERROR(B6/AVERAGEIFS('Data Preparation'!$H:$H,'Data Preparation'!$A:$A,"Rural+Urban",'Data Preparation'!$D:$D,EDATE(A6,-1))-1,"") -> 0.0085082246 | D6: =B6-$B$2 -> 4.5
A7: 44835 | B7: =AVERAGEIFS('Data Preparation'!$H:$H,'Data Preparation'!$A:$A,"Rural+Urban",'Data Preparation'!$D:$D,A7) -> 179.6 | C7: =IFERROR(B7/AVERAGEIFS('Data Preparation'!$H:$H,'Data Preparation'!$A:$A,"Rural+Urban",'Data Preparation'!$D:$D,EDATE(A7,-1))-1,"") -> 0.010123735 | D7: =B7-$B$2 -> 6.3
A8: 44866 | B8: =AVERAGEIFS('Data Preparation'!$H:$H,'Data Preparation'!$A:$A,"Rural+Urban",'Data Preparation'!$D:$D,A8) -> 178.3 | C8: =IFERROR(B8/AVERAGEIFS('Data Preparation'!$H:$H,'Data Preparation'!$A:$A,"Rural+Urban",'Data Preparation'!$D:$D,EDATE(A8,-1))-1,"") -> -0.0072383073 | D8: =B8-$B$2 -> 5
A9: 44896 | B9: =AVERAGEIFS('Data Preparation'!$H:$H,'Data Preparation'!$A:$A,"Rural+Urban",'Data Preparation'!$D:$D,A9) -> 175.9 | C9: =IFERROR(B9/AVERAGEIFS('Data Preparation'!$H:$H,'Data Preparation'!$A:$A,"Rural+Urban",'Data Preparation'!$D:$D,EDATE(A9,-1))-1,"") -> -0.01346046 | D9: =B9-$B$2 -> 2.6
A10: 44927 | B10: =AVERAGEIFS('Data Preparation'!$H:$H,'Data Preparation'!$A:$A,"Rural+Urban",'Data Preparation'!$D:$D,A10) -> 176.7 | C10: =IFERROR(B10/AVERAGEIFS('Data Preparation'!$H:$H,'Data Preparation'!$A:$A,"Rural+Urban",'Data Preparation'!$D:$D,EDATE(A10,-1))-1,"") -> 0.0045480387 | D10: =B10-$B$2 -> 3.4
A11: 44958 | B11: =AVERAGEIFS('Data Preparation'!$H:$H,'Data Preparation'!$A:$A,"Rural+Urban",'Data Preparation'!$D:$D,A11) -> 177 | C11: =IFERROR(B11/AVERAGEIFS('Data Preparation'!$H:$H,'Data Preparation'!$A:$A,"Rural+Urban",'Data Preparation'!$D:$D,EDATE(A11,-1))-1,"") -> 0.0016977929 | D11: =B11-$B$2 -> 3.7
A12: 44986 | B12: =AVERAGEIFS('Data Preparation'!$H:$H,'Data Preparation'!$A:$A,"Rural+Urban",'Data Preparation'!$D:$D,A12) -> 177 | C12: =IFERROR(B12/AVERAGEIFS('Data Preparation'!$H:$H,'Data Preparation'!$A:$A,"Rural+Urban",'Data Preparation'!$D:$D,EDATE(A12,-1))-1,"") -> 0 | D12: =B12-$B$2 -> 3.7
A13: 45017 | B13: =AVERAGEIFS('Data Preparation'!$H:$H,'Data Preparation'!$A:$A,"Rural+Urban",'Data Preparation'!$D:$D,A13) -> 177.9 | C13: =IFERROR(B13/AVERAGEIFS('Data Preparation'!$H:$H,'Data Preparation'!$A:$A,"Rural+Urban",'Data Preparation'!$D:$D,EDATE(A13,-1))-1,"") -> 0.0050847458 | D13: =B13-$B$2 -> 4.6

Sheet Q4_COVID Impact
A1: Month | B1: General YoY Inflation % | C1: Food Inflation % | D1: COVID Period
A2: 43739 | B2: =IFERROR(AVERAGEIFS('Data Preparation'!$F:$F,'Data Preparation'!$A:$A,"Rural+Urban",'Data Preparation'!$D:$D,A2),"") -> 0.045454545 | C2: =IFERROR(AVERAGEIFS('Data Preparation'!$I:$I,'Data Preparation'!$A:$A,"Rural+Urban",'Data Preparation'!$D:$D,A2),"") -> 0.017687075 | D2: =IF(A2<DATE(2020,3,1),"Pre-COVID",IF(A2=DATE(2020,3,1),"COVID Onset / Mar-20","COVID Period")) -> Pre-COVID
A3: 43770 | B3: =IFERROR(AVERAGEIFS('Data Preparation'!$F:$F,'Data Preparation'!$A:$A,"Rural+Urban",'Data Preparation'!$D:$D,A3),"") -> 0.055397727 | C3: =IFERROR(AVERAGEIFS('Data Preparation'!$I:$I,'Data Preparation'!$A:$A,"Rural+Urban",'Data Preparation'!$D:$D,A3),"") -> 0.015374332 | D3: =IF(A3<DATE(2020,3,1),"Pre-COVID",IF(A3=DATE(2020,3,1),"COVID Onset / Mar-20","COVID Period")) -> Pre-COVID
A4: 43800 | B4: =IFERROR(AVERAGEIFS('Data Preparation'!$F:$F,'Data Preparation'!$A:$A,"Rural+Urban",'Data Preparation'!$D:$D,A4),"") -> 0.073518915 | C4: =IFERROR(AVERAGEIFS('Data Preparation'!$I:$I,'Data Preparation'!$A:$A,"Rural+Urban",'Data Preparation'!$D:$D,A4),"") -> 0.020408163 | D4: =IF(A4<DATE(2020,3,1),"Pre-COVID",IF(A4=DATE(2020,3,1),"COVID Onset / Mar-20","COVID Period")) -> Pre-COVID
A5: 43831 | B5: =IFERROR(AVERAGEIFS('Data Preparation'!$F:$F,'Data Preparation'!$A:$A,"Rural+Urban",'Data Preparation'!$D:$D,A5),"") -> 0.075931232 | C5: =IFERROR(AVERAGEIFS('Data Preparation'!$I:$I,'Data Preparation'!$A:$A,"Rural+Urban",'Data Preparation'!$D:$D,A5),"") -> -0.0096774194 | D5: =IF(A5<DATE(2020,3,1),"Pre-COVID",IF(A5=DATE(2020,3,1),"COVID Onset / Mar-20","COVID Period")) -> Pre-COVID
A6: 43862 | B6: =IFERROR(AVERAGEIFS('Data Preparation'!$F:$F,'Data Preparation'!$A:$A,"Rural+Urban",'Data Preparation'!$D:$D,A6),"") -> 0.065761258 | C6: =IFERROR(AVERAGEIFS('Data Preparation'!$I:$I,'Data Preparation'!$A:$A,"Rural+Urban",'Data Preparation'!$D:$D,A6),"") -> -0.019543974 | D6: =IF(A6<DATE(2020,3,1),"Pre-COVID",IF(A6=DATE(2020,3,1),"COVID Onset / Mar-20","COVID Period")) -> Pre-COVID
A7: 43891 | B7: =IFERROR(AVERAGEIFS('Data Preparation'!$F:$F,'Data Preparation'!$A:$A,"Rural+Urban",'Data Preparation'!$D:$D,A7),"") -> 0.058404558 | C7: =IFERROR(AVERAGEIFS('Data Preparation'!$I:$I,'Data Preparation'!$A:$A,"Rural+Urban",'Data Preparation'!$D:$D,A7),"") -> -0.010631229 | D7: =IF(A7<DATE(2020,3,1),"Pre-COVID",IF(A7=DATE(2020,3,1),"COVID Onset / Mar-20","COVID Period")) -> COVID Onset / Mar-20
A8: 43922 | B8: =IFERROR(AVERAGEIFS('Data Preparation'!$F:$F,'Data Preparation'!$A:$A,"Rural+Urban",'Data Preparation'!$D:$D,A8),"") | C8: =IFERROR(AVERAGEIFS('Data Preparation'!$I:$I,'Data Preparation'!$A:$A,"Rural+Urban",'Data Preparation'!$D:$D,A8),"") -> 0.016789792 | D8: =IF(A8<DATE(2020,3,1),"Pre-COVID",IF(A8=DATE(2020,3,1),"COVID Onset / Mar-20","COVID Period")) -> COVID Period
A9: 43952 | D9: =IF(A9<DATE(2020,3,1),"Pre-COVID",IF(A9=DATE(2020,3,1),"COVID Onset / Mar-20","COVID Period")) -> COVID Period
A10: 43983 | B10: =IFERROR(AVERAGEIFS('Data Preparation'!$F:$F,'Data Preparation'!$A:$A,"Rural+Urban",'Data Preparation'!$D:$D,A10),"") -> 0.062281316 | C10: =IFERROR(AVERAGEIFS('Data Preparation'!$I:$I,'Data Preparation'!$A:$A,"Rural+Urban",'Data Preparation'!$D:$D,A10),"") | D10: =IF(A10<DATE(2020,3,1),"Pre-COVID",IF(A10=DATE(2020,3,1),"COVID Onset / Mar-20","COVID Period")) -> COVID Period
A11: 44013 | B11: =IFERROR(AVERAGEIFS('Data Preparation'!$F:$F,'Data Preparation'!$A:$A,"Rural+Urban",'Data Preparation'!$D:$D,A11),"") -> 0.052704577 | C11: =IFERROR(AVERAGEIFS('Data Preparation'!$I:$I,'Data Preparation'!$A:$A,"Rural+Urban",'Data Preparation'!$D:$D,A11),"") -> 0 | D11: =IF(A11<DATE(2020,3,1),"Pre-COVID",IF(A11=DATE(2020,3,1),"COVID Onset / Mar-20","COVID Period")) -> COVID Period
A12: 44044 | B12: =IFERROR(AVERAGEIFS('Data Preparation'!$F:$F,'Data Preparation'!$A:$A,"Rural+Urban",'Data Preparation'!$D:$D,A12),"") -> 0.06137931 | C12: =IFERROR(AVERAGEIFS('Data Preparation'!$I:$I,'Data Preparation'!$A:$A,"Rural+Urban",'Data Preparation'!$D:$D,A12),"") -> 0.019480519 | D12: =IF(A12<DATE(2020,3,1),"Pre-COVID",IF(A12=DATE(2020,3,1),"COVID Onset / Mar-20","COVID Period")) -> COVID Period
A13: 44075 | B13: =IFERROR(AVERAGEIFS('Data Preparation'!$F:$F,'Data Preparation'!$A:$A,"Rural+Urban",'Data Preparation'!$D:$D,A13),"") -> 0.061042524 | C13: =IFERROR(AVERAGEIFS('Data Preparation'!$I:$I,'Data Preparation'!$A:$A,"Rural+Urban",'Data Preparation'!$D:$D,A13),"") -> 0.0063694268 | D13: =IF(A13<DATE(2020,3,1),"Pre-COVID",IF(A13=DATE(2020,3,1),"COVID Onset / Mar-20","COVID Period")) -> COVID Period

Sheet Q5_Oil Impact
A1: Month | B1: Imported Oil Price | C1: Oil MoM % | D1: Overall Inflation % | F1: Category | G1: Correlation | H1: Food & Beverages | I1: Pan, Tobacco & Intoxicants | J1: Clothing & Footwear | K1: Housing | L1: Fuel & Light | M1: Household Goods & Services | N1: Health | O1: Transport & Communication | P1: Recreation & Amusement | Q1: Education | R1: Personal Care & Effects | T1: Food MoM | U1: Pan MoM | V1: Clothing MoM | W1: Housing MoM | X1: Fuel MoM | Y1: Household MoM | Z1: Health MoM | AA1: Transport MoM | AB1: Recreation MoM | AC1: Education MoM | AD1: Personal Care MoM
A2: 44197 | B2: 3918.56 | D2: =IFERROR(AVERAGEIFS('Data Preparation'!$F:$F,'Data Preparation'!$A:$A,"Rural+Urban",'Data Preparation'!$B:$B,YEAR(A2),'Data Preparation'!$C:$C,TEXT(A2,"mmmm")),"") -> 0.047270306 | F2: Food & Beverages | G2: =CORREL($C$3:$C$30,$T$3:$T$30) -> 0.22234526 | H2: {=INDEX('Row Data'!$P:$P,290+(ROW()-2)*3)} -> 154.7 | I2: {=INDEX('Row Data'!$Q:$Q,290+(ROW()-2)*3)} -> 186.5 | J2: {=INDEX('Row Data'!$T:$T,290+(ROW()-2)*3)} -> 158.4 | K2: {=INDEX('Row Data'!$U:$U,290+(ROW()-2)*3)} -> 0 | L2: {=INDEX('Row Data'!$V:$V,290+(ROW()-2)*3)} -> 154.4 | M2: {=INDEX('Row Data'!$W:$W,290+(ROW()-2)*3)} -> 154.8 | N2: {=INDEX('Row Data'!$X:$X,290+(ROW()-2)*3)} -> 164.3 | O2: {=INDEX('Row Data'!$Y:$Y,290+(ROW()-2)*3)} -> 150.2 | P2: {=INDEX('Row Data'!$Z:$Z,290+(ROW()-2)*3)} -> 157 | Q2: {=INDEX('Row Data'!$AA:$AA,290+(ROW()-2)*3)} -> 163.6 | R2: {=INDEX('Row Data'!$AB:$AB,290+(ROW()-2)*3)} -> 155.2
A3: 44228 | B3: 4399.41 | C3: =B3/B2-1 -> 0.12271089 | D3: =IFERROR(AVERAGEIFS('Data Preparation'!$F:$F,'Data Preparation'!$A:$A,"Rural+Urban",'Data Preparation'!$B:$B,YEAR(A3),'Data Preparation'!$C:$C,TEXT(A3,"mmmm")),"") -> 0.050301811 | F3: Pan, Tobacco & Intoxicants | G3: =CORREL($C$3:$C$30,$U$3:$U$30) -> -0.046461169 | H3: {=INDEX('Row Data'!$P:$P,290+(ROW()-2)*3)} -> 154.5 | I3: {=INDEX('Row Data'!$Q:$Q,290+(ROW()-2)*3)} -> 186.1 | J3: {=INDEX('Row Data'!$T:$T,290+(ROW()-2)*3)} -> 158.9 | K3: {=INDEX('Row Data'!$U:$U,290+(ROW()-2)*3)} -> - | L3: {=INDEX('Row Data'!$V:$V,290+(ROW()-2)*3)} -> 156 | M3: {=INDEX('Row Data'!$W:$W,290+(ROW()-2)*3)} -> 154.8 | N3: {=INDEX('Row Data'!$X:$X,290+(ROW()-2)*3)} -> 164.6 | O3: {=INDEX('Row Data'!$Y:$Y,290+(ROW()-2)*3)} -> 151.3 | P3: {=INDEX('Row Data'!$Z:$Z,290+(ROW()-2)*3)} -> 157.8 | Q3: {=INDEX('Row Data'!$AA:$AA,290+(ROW()-2)*3)} -> 163.8 | R3: {=INDEX('Row Data'!$AB:$AB,290+(ROW()-2)*3)} -> 153.1 | T3: =IFERROR(H3/H2-1,"") -> -0.0012928248 | U3: =IFERROR(I3/I2-1,"") -> -0.0021447721 | V3: =IFERROR(J3/J2-1,"") -> 0.0031565657 | W3: =IFERROR(K3/K2-1,"") | X3: =IFERROR(L3/L2-1,"") -> 0.010362694 | Y3: =IFERROR(M3/M2-1,"") -> 0 | Z3: =IFERROR(N3/N2-1,"") -> 0.0018259282 | AA3: =IFERROR(O3/O2-1,"") -> 0.0073235686 | ... AD3: =IFERROR(R3/R2-1,"") -> -0.013530928
A4: 44256 | B4: 4646.36 | C4: =B4/B3-1 -> 0.056132527 | D4: =IFERROR(AVERAGEIFS('Data Preparation'!$F:$F,'Data Preparation'!$A:$A,"Rural+Urban",'Data Preparation'!$B:$B,YEAR(A4),'Data Preparation'!$C:$C,TEXT(A4,"mmmm")),"") -> 0.055181696 | F4: Clothing & Footwear | G4: =CORREL($C$3:$C$30,$V$3:$V$30) -> 0.010204545 | H4: {=INDEX('Row Data'!$P:$P,290+(ROW()-2)*3)} -> 155.6 | I4: {=INDEX('Row Data'!$Q:$Q,290+(ROW()-2)*3)} -> 186.8 | J4: {=INDEX('Row Data'!$T:$T,290+(ROW()-2)*3)} -> 159.9 | K4: {=INDEX('Row Data'!$U:$U,290+(ROW()-2)*3)} -> - | L4: {=INDEX('Row Data'!$V:$V,290+(ROW()-2)*3)} -> 156 | M4: {=INDEX('Row Data'!$W:$W,290+(ROW()-2)*3)} -> 155.5 | N4: {=INDEX('Row Data'!$X:$X,290+(ROW()-2)*3)} -> 165.3 | O4: {=INDEX('Row Data'!$Y:$Y,290+(ROW()-2)*3)} -> 151.7 | P4: {=INDEX('Row Data'!$Z:$Z,290+(ROW()-2)*3)} -> 158.6 | Q4: {=INDEX('Row Data'!$AA:$AA,290+(ROW()-2)*3)} -> 164.1 | R4: {=INDEX('Row Data'!$AB:$AB,290+(ROW()-2)*3)} -> 154.6 | T4: =IFERROR(H4/H3-1,"") -> 0.0071197411 | U4: =IFERROR(I4/I3-1,"") -> 0.0037614186 | V4: =IFERROR(J4/J3-1,"") -> 0.0062932662 | W4: =IFERROR(K4/K3-1,"") | X4: =IFERROR(L4/L3-1,"") -> 0 | Y4: =IFERROR(M4/M3-1,"") -> 0.0045219638 | Z4: =IFERROR(N4/N3-1,"") -> 0.0042527339 | AA4: =IFERROR(O4/O3-1,"") -> 0.0026437541 | ... AD4: =IFERROR(R4/R3-1,"") -> 0.009797518
A5: 44287 | B5: 4684.64 | C5: =B5/B4-1 -> 0.0082387073 | D5: =IFERROR(AVERAGEIFS('Data Preparation'!$F:$F,'Data Preparation'!$A:$A,"Rural+Urban",'Data Preparation'!$B:$B,YEAR(A5),'Data Preparation'!$C:$C,TEXT(A5,"mmmm")),"") | F5: Housing | G5: NA | H5: {=INDEX('Row Data'!$P:$P,290+(ROW()-2)*3)} -> 158.7 | I5: {=INDEX('Row Data'!$Q:$Q,290+(ROW()-2)*3)} -> 189.6 | J5: {=INDEX('Row Data'!$T:$T,290+(ROW()-2)*3)} -> 164.5 | K5: {=INDEX('Row Data'!$U:$U,290+(ROW()-2)*3)} -> 0 | L5: {=INDEX('Row Data'!$V:$V,290+(ROW()-2)*3)} -> 161.7 | M5: {=INDEX('Row Data'!$W:$W,290+(ROW()-2)*3)} -> 158.8 | N5: {=INDEX('Row Data'!$X:$X,290+(ROW()-2)*3)} -> 169.1 | O5: {=INDEX('Row Data'!$Y:$Y,290+(ROW()-2)*3)} -> 153.2 | P5: {=INDEX('Row Data'!$Z:$Z,290+(ROW()-2)*3)} -> 160 | Q5: {=INDEX('Row Data'!$AA:$AA,290+(ROW()-2)*3)} -> 167.6 | R5: {=INDEX('Row Data'!$AB:$AB,290+(ROW()-2)*3)} -> 159.3 | T5: =IFERROR(H5/H4-1,"") -> 0.019922879 | U5: =IFERROR(I5/I4-1,"") -> 0.014989293 | V5: =IFERROR(J5/J4-1,"") -> 0.02876798 | W5: =IFERROR(K5/K4-1,"") | X5: =IFERROR(L5/L4-1,"") -> 0.036538462 | Y5: =IFERROR(M5/M4-1,"") -> 0.021221865 | Z5: =IFERROR(N5/N4-1,"") -> 0.022988506 | AA5: =IFERROR(O5/O4-1,"") -> 0.0098879367 | ... AD5: =IFERROR(R5/R4-1,"") -> 0.030401035
A6: 44317 | B6: 4870.98 | C6: =B6/B5-1 -> 0.039776802 | D6: =IFERROR(AVERAGEIFS('Data Preparation'!$F:$F,'Data Preparation'!$A:$A,"Rural+Urban",'Data Preparation'!$B:$B,YEAR(A6),'Data Preparation'!$C:$C,TEXT(A6,"mmmm")),"") | F6: Fuel & Light | G6: =CORREL($C$3:$C$30,$X$3:$X$30) -> 0.32759823 | H6: {=INDEX('Row Data'!$P:$P,290+(ROW()-2)*3)} -> 160.5 | I6: {=INDEX('Row Data'!$Q:$Q,290+(ROW()-2)*3)} -> 189.1 | J6: {=INDEX('Row Data'!$T:$T,290+(ROW()-2)*3)} -> 164.6 | K6: {=INDEX('Row Data'!$U:$U,290+(ROW()-2)*3)} -> 0 | L6: {=INDEX('Row Data'!$V:$V,290+(ROW()-2)*3)} -> 162.1 | M6: {=INDEX('Row Data'!$W:$W,290+(ROW()-2)*3)} -> 159.2 | N6: {=INDEX('Row Data'!$X:$X,290+(ROW()-2)*3)} -> 169.7 | O6: {=INDEX('Row Data'!$Y:$Y,290+(ROW()-2)*3)} -> 154.2 | P6: {=INDEX('Row Data'!$Z:$Z,290+(ROW()-2)*3)} -> 160.4 | Q6: {=INDEX('Row Data'!$AA:$AA,290+(ROW()-2)*3)} -> 166.8 | R6: {=INDEX('Row Data'!$AB:$AB,290+(ROW()-2)*3)} -> 159.4 | T6: =IFERROR(H6/H5-1,"") -> 0.011342155 | U6: =IFERROR(I6/I5-1,"") -> -0.0026371308 | V6: =IFERROR(J6/J5-1,"") -> 0.00060790274 | W6: =IFERROR(K6/K5-1,"") | X6: =IFERROR(L6/L5-1,"") -> 0.0024737168 | Y6: =IFERROR(M6/M5-1,"") -> 0.0025188917 | Z6: =IFERROR(N6/N5-1,"") -> 0.0035481963 | AA6: =IFERROR(O6/O5-1,"") -> 0.0065274151 | ... AD6: =IFERROR(R6/R5-1,"") -> 0.00062774639
A7: 44348 | B7: 5281.48 | C7: =B7/B6-1 -> 0.084274622 | D7: =IFERROR(AVERAGEIFS('Data Preparation'!$F:$F,'Data Preparation'!$A:$A,"Rural+Urban",'Data Preparation'!$B:$B,YEAR(A7),'Data Preparation'!$C:$C,TEXT(A7,"mmmm")),"") -> 0.062582345 | F7: Household Goods & Services | G7: =CORREL($C$3:$C$30,$Y$3:$Y$30) -> -0.029660894 | H7: {=INDEX('Row Data'!$P:$P,290+(ROW()-2)*3)} -> 161.7 | I7: {=INDEX('Row Data'!$Q:$Q,290+(ROW()-2)*3)} -> 189.7 | J7: {=INDEX('Row Data'!$T:$T,290+(ROW()-2)*3)} -> 165.3 | K7: {=INDEX('Row Data'!$U:$U,290+(ROW()-2)*3)} -> 0 | L7: {=INDEX('Row Data'!$V:$V,290+(ROW()-2)*3)} -> 162.5 | M7: {=INDEX('Row Data'!$W:$W,290+(ROW()-2)*3)} -> 160.3 | N7: {=INDEX('Row Data'!$X:$X,290+(ROW()-2)*3)} -> 170.4 | O7: {=INDEX('Row Data'!$Y:$Y,290+(ROW()-2)*3)} -> 157.1 | P7: {=INDEX('Row Data'!$Z:$Z,290+(ROW()-2)*3)} -> 160.7 | Q7: {=INDEX('Row Data'!$AA:$AA,290+(ROW()-2)*3)} -> 167.2 | R7: {=INDEX('Row Data'!$AB:$AB,290+(ROW()-2)*3)} -> 160.4 | T7: =IFERROR(H7/H6-1,"") -> 0.0074766355 | U7: =IFERROR(I7/I6-1,"") -> 0.0031729244 | V7: =IFERROR(J7/J6-1,"") -> 0.0042527339 | W7: =IFERROR(K7/K6-1,"") | X7: =IFERROR(L7/L6-1,"") -> 0.0024676126 | Y7: =IFERROR(M7/M6-1,"") -> 0.0069095477 | Z7: =IFERROR(N7/N6-1,"") -> 0.0041249263 | AA7: =IFERROR(O7/O6-1,"") -> 0.018806744 | ... AD7: =IFERROR(R7/R6-1,"") -> 0.0062735257
A8: 44378 | B8: 5460.9 | C8: =B8/B7-1 -> 0.033971538 | D8: =IFERROR(AVERAGEIFS('Data Preparation'!$F:$F,'Data Preparation'!$A:$A,"Rural+Urban",'Data Preparation'!$B:$B,YEAR(A8),'Data Preparation'!$C:$C,TEXT(A8,"mmmm")),"") -> 0.070487484 | F8: Health | G8: =CORREL($C$3:$C$30,$Z$3:$Z$30) -> -0.076397654 | H8: {=INDEX('Row Data'!$P:$P,290+(ROW()-2)*3)} -> 161.8 | I8: {=INDEX('Row Data'!$Q:$Q,290+(ROW()-2)*3)} -> 190.2 | J8: {=INDEX('Row Data'!$T:$T,290+(ROW()-2)*3)} -> 166.3 | K8: {=INDEX('Row Data'!$U:$U,290+(ROW()-2)*3)} -> 0 | L8: {=INDEX('Row Data'!$V:$V,290+(ROW()-2)*3)} -> 163.1 | M8: {=INDEX('Row Data'!$W:$W,290+(ROW()-2)*3)} -> 160.9 | N8: {=INDEX('Row Data'!$X:$X,290+(ROW()-2)*3)} -> 171.1 | O8: {=INDEX('Row Data'!$Y:$Y,290+(ROW()-2)*3)} -> 157.7 | P8: {=INDEX('Row Data'!$Z:$Z,290+(ROW()-2)*3)} -> 161.1 | Q8: {=INDEX('Row Data'!$AA:$AA,290+(ROW()-2)*3)} -> 167.5 | R8: {=INDEX('Row Data'!$AB:$AB,290+(ROW()-2)*3)} -> 160.3 | T8: =IFERROR(H8/H7-1,"") -> 0.00061842919 | U8: =IFERROR(I8/I7-1,"") -> 0.0026357406 | V8: =IFERROR(J8/J7-1,"") -> 0.0060496068 | W8: =IFERROR(K8/K7-1,"") | X8: =IFERROR(L8/L7-1,"") -> 0.0036923077 | Y8: =IFERROR(M8/M7-1,"") -> 0.0037429819 | Z8: =IFERROR(N8/N7-1,"") -> 0.0041079812 | AA8: =IFERROR(O8/O7-1,"") -> 0.0038192234 | ... AD8: =IFERROR(R8/R7-1,"") -> -0.0006234414
A9: 44409 | B9: 5108.73 | C9: =B9/B8-1 -> -0.06448937 | D9: =IFERROR(AVERAGEIFS('Data Preparation'!$F:$F,'Data Preparation'!$A:$A,"Rural+Urban",'Data Preparation'!$B:$B,YEAR(A9),'Data Preparation'!$C:$C,TEXT(A9,"mmmm")),"") -> 0.06042885 | F9: Transport & Communication | G9: =CORREL($C$3:$C$30,$AA$3:$AA$30) -> 0.32024081 | H9: {=INDEX('Row Data'!$P:$P,290+(ROW()-2)*3)} -> 162.1 | I9: {=INDEX('Row Data'!$Q:$Q,290+(ROW()-2)*3)} -> 190.5 | J9: {=INDEX('Row Data'!$T:$T,290+(ROW()-2)*3)} -> 167.1 | K9: {=INDEX('Row Data'!$U:$U,290+(ROW()-2)*3)} -> 0 | L9: {=INDEX('Row Data'!$V:$V,290+(ROW()-2)*3)} -> 163.7 | M9: {=INDEX('Row Data'!$W:$W,290+(ROW()-2)*3)} -> 161.3 | N9: {=INDEX('Row Data'!$X:$X,290+(ROW()-2)*3)} -> 171.9 | O9: {=INDEX('Row Data'!$Y:$Y,290+(ROW()-2)*3)} -> 157.8 | P9: {=INDEX('Row Data'!$Z:$Z,290+(ROW()-2)*3)} -> 162.7 | Q9: {=INDEX('Row Data'!$AA:$AA,290+(ROW()-2)*3)} -> 168.5 | R9: {=INDEX('Row Data'!$AB:$AB,290+(ROW()-2)*3)} -> 160.2 | T9: =IFERROR(H9/H8-1,"") -> 0.0018541409 | U9: =IFERROR(I9/I8-1,"") -> 0.0015772871 | V9: =IFERROR(J9/J8-1,"") -> 0.0048105833 | W9: =IFERROR(K9/K8-1,"") | X9: =IFERROR(L9/L8-1,"") -> 0.0036787247 | Y9: =IFERROR(M9/M8-1,"") -> 0.0024860162 | Z9: =IFERROR(N9/N8-1,"") -> 0.0046756283 | AA9: =IFERROR(O9/O8-1,"") -> 0.00063411541 | ... AD9: =IFERROR(R9/R8-1,"") -> -0.00062383032
A10: 44440 | B10: 5359.17 | C10: =B10/B9-1 -> 0.049021968 | D10: =IFERROR(AVERAGEIFS('Data Preparation'!$F:$F,'Data Preparation'!$A:$A,"Rural+Urban",'Data Preparation'!$B:$B,YEAR(A10),'Data Preparation'!$C:$C,TEXT(A10,"mmmm")),"") -> 0.054945055 | F10: Recreation & Amusement | G10: =CORREL($C$3:$C$30,$AB$3:$AB$30) -> -0.015757863 | H10: {=INDEX('Row Data'!$P:$P,290+(ROW()-2)*3)} -> 165.5 | I10: {=INDEX('Row Data'!$Q:$Q,290+(ROW()-2)*3)} -> 191.2 | J10: {=INDEX('Row Data'!$T:$T,290+(ROW()-2)*3)} -> 168.3 | K10: {=INDEX('Row Data'!$U:$U,290+(ROW()-2)*3)} -> 0 | L10: {=INDEX('Row Data'!$V:$V,290+(ROW()-2)*3)} -> 165.5 | M10: {=INDEX('Row Data'!$W:$W,290+(ROW()-2)*3)} -> 162 | N10: {=INDEX('Row Data'!$X:$X,290+(ROW()-2)*3)} -> 172.5 | O10: {=INDEX('Row Data'!$Y:$Y,290+(ROW()-2)*3)} -> 159.5 | P10: {=INDEX('Row Data'!$Z:$Z,290+(ROW()-2)*3)} -> 163.2 | Q10: {=INDEX('Row Data'!$AA:$AA,290+(ROW()-2)*3)} -> 169 | R10: {=INDEX('Row Data'!$AB:$AB,290+(ROW()-2)*3)} -> 161.1 | T10: =IFERROR(H10/H9-1,"") -> 0.020974707 | U10: =IFERROR(I10/I9-1,"") -> 0.0036745407 | V10: =IFERROR(J10/J9-1,"") -> 0.0071813285 | W10: =IFERROR(K10/K9-1,"") | X10: =IFERROR(L10/L9-1,"") -> 0.010995724 | Y10: =IFERROR(M10/M9-1,"") -> 0.0043397396 | Z10: =IFERROR(N10/N9-1,"") -> 0.0034904014 | AA10: =IFERROR(O10/O9-1,"") -> 0.010773131 | ... AD10: =IFERROR(R10/R9-1,"") -> 0.0056179775
A11: 44470 | B11: 6146.58 | C11: =B11/B10-1 -> 0.1469276 | D11: =IFERROR(AVERAGEIFS('Data Preparation'!$F:$F,'Data Preparation'!$A:$A,"Rural+Urban",'Data Preparation'!$B:$B,YEAR(A11),'Data Preparation'!$C:$C,TEXT(A11,"mmmm")),"") -> 0.058184143 | F11: Education | G11: =CORREL($C$3:$C$30,$AC$3:$AC$30) -> -0.11071667 | H11: {=INDEX('Row Data'!$P:$P,290+(ROW()-2)*3)} -> 167.5 | I11: {=INDEX('Row Data'!$Q:$Q,290+(ROW()-2)*3)} -> 191.4 | J11: {=INDEX('Row Data'!$T:$T,290+(ROW()-2)*3)} -> 169.8 | K11: {=INDEX('Row Data'!$U:$U,290+(ROW()-2)*3)} -> 0 | L11: {=INDEX('Row Data'!$V:$V,290+(ROW()-2)*3)} -> 165.3 | M11: {=INDEX('Row Data'!$W:$W,290+(ROW()-2)*3)} -> 162.9 | N11: {=INDEX('Row Data'!$X:$X,290+(ROW()-2)*3)} -> 173.4 | O11: {=INDEX('Row Data'!$Y:$Y,290+(ROW()-2)*3)} -> 158.9 | P11: {=INDEX('Row Data'!$Z:$Z,290+(ROW()-2)*3)} -> 163.8 | Q11: {=INDEX('Row Data'!$AA:$AA,290+(ROW()-2)*3)} -> 169.3 | R11: {=INDEX('Row Data'!$AB:$AB,290+(ROW()-2)*3)} -> 162.4 | T11: =IFERROR(H11/H10-1,"") -> 0.012084592 | U11: =IFERROR(I11/I10-1,"") -> 0.0010460251 | V11: =IFERROR(J11/J10-1,"") -> 0.008912656 | W11: =IFERROR(K11/K10-1,"") | X11: =IFERROR(L11/L10-1,"") -> -0.0012084592 | Y11: =IFERROR(M11/M10-1,"") -> 0.0055555556 | Z11: =IFERROR(N11/N10-1,"") -> 0.0052173913 | AA11: =IFERROR(O11/O10-1,"") -> -0.0037617555 | ... AD11: =IFERROR(R11/R10-1,"") -> 0.008069522
A12: 44501 | B12: 5952.69 | C12: =B12/B11-1 -> -0.031544371 | D12: =IFERROR(AVERAGEIFS('Data Preparation'!$F:$F,'Data Preparation'!$A:$A,"Rural+Urban",'Data Preparation'!$B:$B,YEAR(A12),'Data Preparation'!$C:$C,TEXT(A12,"mmmm")),"") -> 0.05239899 | F12: Personal Care & Effects | G12: =CORREL($C$3:$C$30,$AD$3:$AD$30) -> 0.003585364 | H12: {=INDEX('Row Data'!$P:$P,290+(ROW()-2)*3)} -> 165.8 | I12: {=INDEX('Row Data'!$Q:$Q,290+(ROW()-2)*3)} -> 190.8 | J12: {=INDEX('Row Data'!$T:$T,290+(ROW()-2)*3)} -> 171.2 | K12: {=INDEX('Row Data'!$U:$U,290+(ROW()-2)*3)} -> 0 | L12: {=INDEX('Row Data'!$V:$V,290+(ROW()-2)*3)} -> 165.6 | M12: {=INDEX('Row Data'!$W:$W,290+(ROW()-2)*3)} -> 163.9 | N12: {=INDEX('Row Data'!$X:$X,290+(ROW()-2)*3)} -> 174 | O12: {=INDEX('Row Data'!$Y:$Y,290+(ROW()-2)*3)} -> 160.1 | P12: {=INDEX('Row Data'!$Z:$Z,290+(ROW()-2)*3)} -> 164.5 | Q12: {=INDEX('Row Data'!$AA:$AA,290+(ROW()-2)*3)} -> 169.7 | R12: {=INDEX('Row Data'!$AB:$AB,290+(ROW()-2)*3)} -> 162.8 | T12: =IFERROR(H12/H11-1,"") -> -0.010149254 | U12: =IFERROR(I12/I11-1,"") -> -0.0031347962 | V12: =IFERROR(J12/J11-1,"") -> 0.0082449941 | W12: =IFERROR(K12/K11-1,"") | X12: =IFERROR(L12/L11-1,"") -> 0.001814882 | Y12: =IFERROR(M12/M11-1,"") -> 0.0061387354 | Z12: =IFERROR(N12/N11-1,"") -> 0.0034602076 | AA12: =IFERROR(O12/O11-1,"") -> 0.0075519194 | ... AD12: =IFERROR(R12/R11-1,"") -> 0.0024630542
A13: 44531 | B13: 5504.55 | C13: =B13/B12-1 -> -0.075283611 | D13: =IFERROR(AVERAGEIFS('Data Preparation'!$F:$F,'Data Preparation'!$A:$A,"Rural+Urban",'Data Preparation'!$B:$B,YEAR(A13),'Data Preparation'!$C:$C,TEXT(A13,"mmmm")),"") -> 0.045940843 | H13: {=INDEX('Row Data'!$P:$P,290+(ROW()-2)*3)} -> 164.1 | I13: {=INDEX('Row Data'!$Q:$Q,290+(ROW()-2)*3)} -> 190.7 | J13: {=INDEX('Row Data'!$T:$T,290+(ROW()-2)*3)} -> 172.7 | K13: {=INDEX('Row Data'!$U:$U,290+(ROW()-2)*3)} -> 0 | L13: {=INDEX('Row Data'!$V:$V,290+(ROW()-2)*3)} -> 165.8 | M13: {=INDEX('Row Data'!$W:$W,290+(ROW()-2)*3)} -> 164.9 | N13: {=INDEX('Row Data'!$X:$X,290+(ROW()-2)*3)} -> 174.7 | O13: {=INDEX('Row Data'!$Y:$Y,290+(ROW()-2)*3)} -> 160.8 | P13: {=INDEX('Row Data'!$Z:$Z,290+(ROW()-2)*3)} -> 164.9 | Q13: {=INDEX('Row Data'!$AA:$AA,290+(ROW()-2)*3)} -> 169.9 | R13: {=INDEX('Row Data'!$AB:$AB,290+(ROW()-2)*3)} -> 163.2 | T13: =IFERROR(H13/H12-1,"") -> -0.010253317 | U13: =IFERROR(I13/I12-1,"") -> -0.00052410901 | V13: =IFERROR(J13/J12-1,"") -> 0.0087616822 | W13: =IFERROR(K13/K12-1,"") | X13: =IFERROR(L13/L12-1,"") -> 0.0012077295 | Y13: =IFERROR(M13/M12-1,"") -> 0.0061012813 | Z13: =IFERROR(N13/N12-1,"") -> 0.0040229885 | AA13: =IFERROR(O13/O12-1,"") -> 0.0043722673 | ... AD13: =IFERROR(R13/R12-1,"") -> 0.0024570025
A14: 44562 | B14: 6247.71 | C14: =B14/B13-1 -> 0.13500831 | D14: =IFERROR(AVERAGEIFS('Data Preparation'!$F:$F,'Data Preparation'!$A:$A,"Rural+Urban",'Data Preparation'!$B:$B,YEAR(A14),'Data Preparation'!$C:$C,TEXT(A14,"mmmm")),"") -> 0.053401144 | H14: {=INDEX('Row Data'!$P:$P,290+(ROW()-2)*3)} -> 163.9 | I14: {=INDEX('Row Data'!$Q:$Q,290+(ROW()-2)*3)} -> 191.5 | J14: {=INDEX('Row Data'!$T:$T,290+(ROW()-2)*3)} -> 173.7 | K14: {=INDEX('Row Data'!$U:$U,290+(ROW()-2)*3)} -> 0 | L14: {=INDEX('Row Data'!$V:$V,290+(ROW()-2)*3)} -> 167.4 | M14: {=INDEX('Row Data'!$W:$W,290+(ROW()-2)*3)} -> 165.7 | N14: {=INDEX('Row Data'!$X:$X,290+(ROW()-2)*3)} -> 175.3 | O14: {=INDEX('Row Data'!$Y:$Y,290+(ROW()-2)*3)} -> 161.2 | P14: {=INDEX('Row Data'!$Z:$Z,290+(ROW()-2)*3)} -> 165.5 | Q14: {=INDEX('Row Data'!$AA:$AA,290+(ROW()-2)*3)} -> 170.3 | R14: {=INDEX('Row Data'!$AB:$AB,290+(ROW()-2)*3)} -> 164.5 | T14: =IFERROR(H14/H13-1,"") -> -0.001218769 | U14: =IFERROR(I14/I13-1,"") -> 0.0041950708 | V14: =IFERROR(J14/J13-1,"") -> 0.005790388 | W14: =IFERROR(K14/K13-1,"") | X14: =IFERROR(L14/L13-1,"") -> 0.0096501809 | Y14: =IFERROR(M14/M13-1,"") -> 0.0048514251 | Z14: =IFERROR(N14/N13-1,"") -> 0.0034344591 | AA14: =IFERROR(O14/O13-1,"") -> 0.0024875622 | ... AD14: =IFERROR(R14/R13-1,"") -> 0.0079656863
A15: 44593 | B15: 7018.51 | C15: =B15/B14-1 -> 0.1233732 | D15: =IFERROR(AVERAGEIFS('Data Preparation'!$F:$F,'Data Preparation'!$A:$A,"Rural+Urban",'Data Preparation'!$B:$B,YEAR(A15),'Data Preparation'!$C:$C,TEXT(A15,"mmmm")),"") -> 0.060664112 | H15: {=INDEX('Row Data'!$P:$P,290+(ROW()-2)*3)} -> 166.6 | I15: {=INDEX('Row Data'!$Q:$Q,290+(ROW()-2)*3)} -> 192.3 | J15: {=INDEX('Row Data'!$T:$T,290+(ROW()-2)*3)} -> 175.1 | K15: {=INDEX('Row Data'!$U:$U,290+(ROW()-2)*3)} -> 0 | L15: {=INDEX('Row Data'!$V:$V,290+(ROW()-2)*3)} -> 168.9 | M15: {=INDEX('Row Data'!$W:$W,290+(ROW()-2)*3)} -> 166.5 | N15: {=INDEX('Row Data'!$X:$X,290+(ROW()-2)*3)} -> 176 | O15: {=INDEX('Row Data'!$Y:$Y,290+(ROW()-2)*3)} -> 162 | P15: {=INDEX('Row Data'!$Z:$Z,290+(ROW()-2)*3)} -> 166.6 | Q15: {=INDEX('Row Data'!$AA:$AA,290+(ROW()-2)*3)} -> 170.6 | R15: {=INDEX('Row Data'!$AB:$AB,290+(ROW()-2)*3)} -> 167.4 | T15: =IFERROR(H15/H14-1,"") -> 0.016473459 | U15: =IFERROR(I15/I14-1,"") -> 0.0041775457 | V15: =IFERROR(J15/J14-1,"") -> 0.0080598733 | W15: =IFERROR(K15/K14-1,"") | X15: =IFERROR(L15/L14-1,"") -> 0.0089605735 | Y15: =IFERROR(M15/M14-1,"") -> 0.0048280024 | Z15: =IFERROR(N15/N14-1,"") -> 0.0039931546 | AA15: =IFERROR(O15/O14-1,"") -> 0.0049627792 | ... AD15: =IFERROR(R15/R14-1,"") -> 0.017629179
